Workbook

Sheet Overview
B2: DCF Model & Key Ratios
B4: Target Price | C4: =DCF!C22 -> 377.16847
B5: Implied Upside | C5: =DCF!C25 -> 0.30856772
B7: ROIC | C7: =IS!G36/SUM(BS!G42,BS!G30:G31,BS!G26:G27) -> 0.13736776
B8: ROE | C8: =IS!G36/BS!G42 -> 0.1566519
B9: Operating Ratio | C9: =IS!G24/IS!G5 -> 0.84975105
C11: Actual | D11: Implied
B12: EV/EBITDA | C12: =(292*IS!G40+WACC!C13-BS!G6)/IS!G38 -> 11.713496 | D12: =DCF!C19/IS!G38 -> 15.058575
B13: P/E | C13: =IS!G47 -> 33.58 | D13: =DCF!C22/IS!G44 -> 27.917726
B14: EV/Sales | C14: =(292*IS!G40+WACC!C13-BS!G6)/IS!G5 -> 2.5268482 | D14: =DCF!C19/IS!G5 -> 3.2484525
B15: PEG | C15: {=(292/IS!G41)/((POWER(PRODUCT(1+IS!E45:G45),1/3)-1)*100)} -> 1.7168251 | D15: =(DCF!C22/IS!G44)/(GEOMEAN(IS!H45:L45)*100) -> 2.3685155
B36: Financial Forecasts
B126: Capital Structure
B128: Total Debt | C128: =BS!G34 -> 855586
B129: Total Equity | C129: =BS!G42 -> 2311271
B131: Debt-to-Equity | C131: =C128/C129 -> 0.37017987
B132: Capitalisation Ratio | C132: =C128/(C129+C128) -> 0.27016881
B133: Cash Ratio | C133: =SUM(BS!G6)/BS!G28 -> 0.069956172
B134: Current Ratio | C134: =BS!G11/BS!G28 -> 1.5654871
B135: Debt Ratio (D/A) | C135: =BS!G34/BS!G19 -> 0.27016881
B136: Long-term Debt to Capitalisation | C136: =SUM(BS!G30:G33)/SUM(BS!G30:G33,BS!G38:G39) -> 0.66168401
B158: Breakeven Analysis
B160: Year | C160: 2020 | D160: 2021 | E160: 2022 | F160: 2023 | G160: 2024 | H160: 2025 | I160: 2026 | J160: 2027 | K160: 2028 | L160: 2029
B161: Breakeven ($bn) | C161: =IS!C24/1000000 -> 1.642045 | D161: =IS!D24/1000000 -> 1.953563 | E161: =IS!E24/1000000 -> 2.321569 | F161: =IS!F24/1000000 -> 2.420937 | G161: =IS!G24/1000000 -> 2.726914 | H161: =IS!H24/1000000 -> 2.9998006 | I161: =IS!I24/1000000 -> 3.2461326 | J161: =IS!J24/1000000 -> 3.5169471 | ... L161: =IS!L24/1000000 -> 4.1410025
B162: Revenue ($bn) | C162: =IS!C5/1000000 -> 1.822366 | D162: =IS!D5/1000000 -> 2.288704 | E162: =IS!E5/1000000 -> 2.792057 | F162: =IS!F5/1000000 -> 2.881433 | G162: =IS!G5/1000000 -> 3.209074 | H162: =IS!H5/1000000 -> 3.5070419 | I162: =IS!I5/1000000 -> 3.8326767 | J162: =IS!J5/1000000 -> 4.1885472 | ... L162: =IS!L5/1000000 -> 5.0024858
B163: Safety Margin | C163: =(IS!C5-IS!C18)/IS!C18 -> 0.20692986 | D163: =(IS!D5-IS!D18)/IS!D18 -> 0.26046724 | E163: =(IS!E5-IS!E18)/IS!E18 -> 0.29004075 | F163: =(IS!F5-IS!F18)/IS!F18 -> 0.28567535 | G163: =(IS!G5-IS!G18)/IS!G18 -> 0.27732845 | H163: =(IS!H5-IS!H18)/IS!H18 -> 0.32913805 | I163: =(IS!I5-IS!I18)/IS!I18 -> 0.34414986 | J163: =(IS!J5-IS!J18)/IS!J18 -> 0.35747766 | ... L163: =(IS!L5-IS!L18)/IS!L18 -> 0.37970746

Sheet Charts (Hidden)
B2: Factor | C2: Min | D2: Bear | E2: Base | F2: Bull | G2: Max | H2: Display Order
B3: Scenario Analysis | C3: -0.45732584 | D3: 0.018665662 | E3: 0.2918 | F3: 0.43845469 | G3: 0.94687992 | H3: 1
B4: Revenue +/- 5% | C4: -0.022878279 | D4: 0.12815946 | E4: 0.2918 | F4: 0.46876498 | G4: 0.65994246 | H4: 2
B5: WACC/TGR | C5: 0.1556 | D5: 0.2101 | E5: 0.2918 | F5: 0.3613 | G5: 0.4125 | H5: 3
A7: Football Field | B7: Scenario Analysis | C7: Revenue +/- 5% | D7: WACC/TGR
B8: -0.45732584 | C8: -0.022878279 | D8: 0.1556
B9: 0.018665662 | C9: 0.12815946 | D9: 0.2101
B10: 0.2918 | C10: 0.2918 | D10: 0.2918
B11: 0.43845469 | C11: 0.46876498 | D11: 0.3613
B12: 0.94687992 | C12: 0.65994246 | D12: 0.4125
B14: 2020 | C14: 2021 | D14: 2022 | E14: 2023 | F14: 2024 | G14: 2025 | H14: 2026 | I14: 2027 | J14: 2028 | K14: 2029
A15: ROIC | B15: =IS!C36/SUM(BS!C42,BS!C30:C31,BS!C26:C27) -> 0.12052685 | C15: =IS!D36/SUM(BS!D42,BS!D30:D31,BS!D26:D27) -> 0.18340913 | D15: =IS!E36/SUM(BS!E42,BS!E30:E31,BS!E26:E27) -> 0.20614296 | E15: =IS!F36/SUM(BS!F42,BS!F30:F31,BS!F26:F27) -> 0.17058784 | F15: =IS!G36/SUM(BS!G42,BS!G30:G31,BS!G26:G27) -> 0.13736776 | G15: =IS!H25/($I$22*POWER(1+$J$22,COLUMN(G13)-COLUMN($F$13))) -> 0.14166672 | H15: =IS!I25/($I$22*POWER(1+$J$22,COLUMN(H13)-COLUMN($F$13))) -> 0.14488906 | I15: =IS!J25/($I$22*POWER(1+$J$22,COLUMN(I13)-COLUMN($F$13))) -> 0.14673284 | J15: =IS!K25/($I$22*POWER(1+$J$22,COLUMN(J13)-COLUMN($F$13))) -> 0.14744717 | K15: =IS!L25/($I$22*POWER(1+$J$22,COLUMN(K13)-COLUMN($F$13))) -> 0.14724036
A16: ROE | B16: =IS!C36/BS!C42 -> 0.14391109 | C16: =IS!D36/BS!D42 -> 0.20751303 | D16: =IS!E36/BS!E42 -> 0.22631085 | E16: =IS!F36/BS!F42 -> 0.18277522 | F16: =IS!G36/BS!G42 -> 0.1566519 | G16: =IS!H25/($I$21*POWER(1+$J$21,COLUMN(G13)-COLUMN($F$13))) -> 0.18855848 | H16: =IS!I25/($I$21*POWER(1+$J$21,COLUMN(H13)-COLUMN($F$13))) -> 0.18733308 | I16: =IS!J25/($I$21*POWER(1+$J$21,COLUMN(I13)-COLUMN($F$13))) -> 0.18429217 | J16: =IS!K25/($I$21*POWER(1+$J$21,COLUMN(J13)-COLUMN($F$13))) -> 0.17989398 | K16: =IS!L25/($I$21*POWER(1+$J$21,COLUMN(K13)-COLUMN($F$13))) -> 0.17450494
A18: potential todo: add lines for industry benchmark roic/roe
D21: SE | E21: 961288 | F21: 1220333 | G21: 1579341 | H21: 1941494 | I21: 2311271 | J21: {=AVERAGE(F21:I21/E21:H21-1)/1.5} -> 0.16390533
D22: L+SE | E22: 1548774 | F22: 1845250 | G22: 2174710 | H22: 2583565 | I22: 3166857 | J22: {=(AVERAGE(F22:I22/E22:H22)-1)/1.5} -> 0.13062429
C25: 2020 | D25: 2021 | E25: 2022 | F25: 2023 | G25: 2024 | H25: 2025 | I25: 2026 | J25: 2027 | K25: 2028 | L25: 2029
B26: Salaries, wages and employees’ benefits | C26: 963260 | D26: 1063703 | E26: 1169539 | F26: 1301280 | G26: 1487847 | H26: 1593251.9 | I26: 1741188 | J26: 1902860.2 | K26: 2079544 | L26: 2272633.2
B27: Purchased transportation | C27: 141369 | D27: 249710 | E27: 315896 | F27: 238688 | G27: 237306 | H27: 225440.7 | I27: 214168.66 | J27: 203460 | K27: 193287.22 | L27: 183622.86
B28: Fuel, operating expenses and supplies | C28: 299234 | D28: 381904 | E28: 558456 | F28: 563688 | G28: 629402 | H28: 644907.77 | I28: 704788.54 | J28: 770229.34 | K28: 841746.44 | L28: 919904.01
B29: Operating taxes & licenses, claims, and insurance | C29: =C32+C33 -> 106055 | D29: =D32+D33 -> 120440 | E29: =E32+E33 -> 120425 | F29: =F32+F33 -> 137526 | G29: =G32+G33 -> 157777 | H29: =H32+H33 -> 174983.34 | I29: =I32+I33 -> 191230.84 | J29: =J32+J33 -> 208986.95 | ... L29: =L32+L33 -> 249598.29
B32: Operating taxes and licenses | C32: 56294 | D32: 59095 | E32: 63824 | F32: 69542 | G32: 80128 | H32: 89767.488 | I32: 98102.551 | J32: 107211.54 | K32: 117166.31 | L32: 128045.4
B33: Claims and insurance | C33: 49761 | D33: 61345 | E33: 56601 | F33: 67984 | G33: 77649 | H33: 85215.853 | I33: 93128.289 | J33: 101775.41 | K33: 111225.43 | L33: 121552.89
B36: connect pe ratios:
C37: Trailing P/E | D37: 34.18 | E37: 35.03 | F37: 15.55 | G37: 32.9 | H37: 33.58 | I37: 20.435203 | J37: 17.665311 | K37: 15.429519 | L37: 13.586988 | M37: 12.042925
C38: PEG Ratio | E38: 0.42559813 | F38: 0.37605612 | G38: -31.49 | H38: 17.810832 | I38: 3.5481743 | J38: 1.126626 | K38: 1.0648132 | L38: 1.0019167 | M38: 0.93928851
B41: zero line | C41: 0 | D41: 0 | E41: 0 | F41: 0 | G41: 0 | H41: 0 | I41: 0 | J41: 0 | K41: 0 | L41: 0
B45: debt equity
A47: interest bearing only | C47: 2020 | D47: 2021 | E47: 2022 | F47: 2023 | G47: 2024 | H47: 2025 | I47: 2026 | J47: 2027 | K47: 2028 | L47: 2029
B48: Total Debt | C48: =SUM(BS!C30:C31,BS!C26:C27) -> 186506 | D48: =SUM(BS!D30:D31,BS!D26:D27) -> 160378 | E48: =SUM(BS!E30:E31,BS!E26:E27) -> 154514 | F48: =SUM(BS!F30:F31,BS!F26:F27) -> 138707 | G48: =SUM(BS!G30:G31,BS!G26:G27) -> 324464
B49: Total Equity | C49: =BS!C42 -> 961288 | D49: =BS!D42 -> 1220333 | E49: =BS!E42 -> 1579341 | F49: =BS!F42 -> 1941494 | G49: =BS!G42 -> 2311271
B50: Debt-to-Equity | C50: =C48/C49 -> 0.19401678 | D50: =D48/D49 -> 0.13142151 | E50: =E48/E49 -> 0.097834477 | F50: =F48/F49 -> 0.071443435 | G50: =G48/G49 -> 0.14038336
B51: Capitalisation Ratio | C51: =C48/(C48+C49) -> 0.16249083 | D51: =D48/(D48+D49) -> 0.1161561 | E51: =E48/(E48+E49) -> 0.089115872 | F51: =F48/(F48+F49) -> 0.066679614 | G51: =G48/(G48+G49) -> 0.12310191
B52: Debt Ratio (D/A) | C52: =BS!C34/BS!C19 -> 0.37932326 | D52: =BS!D34/BS!D19 -> 0.33866251 | E52: =BS!E34/BS!E19 -> 0.27376938 | F52: =BS!F34/BS!F19 -> 0.24852133 | G52: =BS!G34/BS!G19 -> 0.27016881
B53: Long-term Debt to Capitalisation | C53: =SUM(BS!C30:C33)/SUM(BS!C30:C33,BS!C42) -> 0.24487596 | D53: =SUM(BS!D30:D33)/SUM(BS!D30:D33,BS!D42) -> 0.19920507 | E53: =SUM(BS!E30:E33)/SUM(BS!E30:E33,BS!E42) -> 0.16904124 | F53: =SUM(BS!F30:F33)/SUM(BS!F30:F33,BS!F42) -> 0.14150507 | G53: =SUM(BS!G30:G33)/SUM(BS!G30:G33,BS!G42) -> 0.19983611
B55: Cash Ratio | C55: =SUM(BS!C6)/BS!C28 -> 0.091777454 | D55: =SUM(BS!D6)/BS!D28 -> 0.33169025 | E55: =SUM(BS!E6)/BS!E28 -> 0.68369301 | F55: =SUM(BS!F6)/BS!F28 -> 0.9197624 | G55: =SUM(BS!G6)/BS!G28 -> 0.069956172 | H55: =SUM(BS!H6)/BS!H28 -> 0.084489626 | I55: =SUM(BS!I6)/BS!I28 -> 0.60579242 | J55: =SUM(BS!J6)/BS!J28 -> 0.82343392 | ... L55: =SUM(BS!L6)/BS!L28 -> 0.74139037
B56: Current Ratio | C56: =BS!C11/BS!C28 -> 0.98528399 | D56: =BS!D11/BS!D28 -> 1.2953403 | E56: =BS!E11/BS!E28 -> 1.9369393 | F56: =BS!F11/BS!F28 -> 2.0142273 | G56: =BS!G11/BS!G28 -> 1.5654871 | H56: =BS!H11/BS!H28 -> 1.3801637 | I56: =BS!I11/BS!I28 -> 1.9439825 | J56: =BS!J11/BS!J28 -> 2.204196 | ... L56: =BS!L11/BS!L28 -> 2.206952

Sheet Inputs & Assumptions
C3: Switchboard
C4: Revenue | D4: 1
C5: Inflation | D5: 1
C6: WACC | D6: 1
C7: TGR | D7: 0.03
C8: Risk Free Rate | D8: 0.0402
B11: Revenue Inputs
B12: ID | C12: Scenario | D12: CAGR | E12: Notes
B13: 1 | C13: Base Case | D13: =GEOMEAN(IS!E6:G6) -> 0.092851686 | E13: Last 3 years (Geometric Average)
B14: 2 | C14: Long-Run | D14: 0.0566 | E14: Set at the US LTL industry CAGR
B15: 3 | C15: Historical | D15: =GEOMEAN(IS!D6:G6) -> 0.11963511 | E15: Based on historical average
B16: 4 | C16: Most Recent | D16: =IS!G6 -> 0.11370766 | E16: Most recent growth
B17: 5 | C17: Saturated Market | D17: =D13 -> 0.092851686 | E17: Declining growth every year
B20: Inflation (Wage/Benefits Projections)
B21: ID | C21: Scenario | D21: Notes | E21: 2025 | F21: 2026 | G21: 2027 | H21: 2028 | I21: 2029
B22: 1 | C22: Base Case | D22: Inflation expected to be higher throughout the Trump term and as the Fed begins to prioritise the unemployment mandate | E22: 0.031 | F22: 0.032 | G22: 0.032 | H22: 0.03 | I22: 0.029
B23: 2 | C23: Sticky/Persistent | D23: Given US political factors, likely a conservative view | E23: 0.031 | F23: 0.03 | G23: 0.03 | H23: 0.03 | I23: 0.03
B24: 3 | C24: Blue Sky | D24: GENIUS Act and rate cuts prove more favourable than expected | E24: 0.031 | F24: 0.029 | G24: 0.025 | H24: 0.022 | I24: 0.02
B27: WACC
B28: ID | C28: WACC | D28: Source/Notes
B29: 1 | C29: =WACC!C2 -> 0.084658433 | D29: Derived from model
B30: 2 | C30: 0.0707 | D30: AlphaSpread.com as of Oct 2025
B31: 3 | C31: 0.087 | D31: valueinvesting.io as of Oct 2025
B32: 4 | C32: 0.1943 | D32: gurufocus.com as of Oct 2025
B35: Assumptions | C35: Item | D35: Notes
B36: =GEOMEAN(IS!$E$9:$G$9) + 0.01 -> 0.45430077 | C36: Income Statement | D36: Employee wages forecasted at historical average of percentage revenue
B37: -0.05 | C37: Income Statement | D37: Purchased transportation is difficult to forecast, negative growth will be forecasted as the company matures
B38: - | C38: Income Statement | D38: The "Fuel, operating expenses and supplies", "Operating taxes and licenses", and "Claims and insurance" line items will be forecasted by historical average as a percentage of revenue
B39: - | C39: Income Statement | D39: Operating losses are negligible
B40: =AVERAGE(IS!D43:G43) -> 0.001970699 | C40: Income Statement | D40: As weighted average shares have been historically very stable, they are projected to grow at a low historical rate
B41: =GEOMEAN(IS!C22:G22) -> 0.10299762 | C41: Income Statement | D41: D&A forecasted at historical average of percentage revenue
B42: =GEOMEAN(IS!C33:G33) -> 0.23357308 | C42: Tax Rate | D42: Tax rate forecasted at historical average, aligns with federal tax rate but fails to account for the complexity of changing state-level and per-truck taxes
B43: =GEOMEAN('Supporting Schedules'!C6:F6) -> 0.13355247 | C43: PP&E Schedule | D43: Capital Expenditures (excluding the anomalous 2024 capex due to the Yellow Corp bankruptcy sale) forecasted as historical average of revenue
B44: - | C44: PP&E Schedule | D44: CapEx for this year is overriden to 625m from the guidance provided in the Q2 earnings call
B45: =GEOMEAN('Supporting Schedules'!C10:E10) -> 0.060365421 | C45: PP&E Schedule | D45: D&A (excluding anomalous 2023/24 figures) forecasted as historical average of 2020-2022 as percentage of revenue
B46: - | C46: PP&E Schedule | D46: Disposals are negligible (<0.1% of revenue over the last 3 years)
B47: =GEOMEAN('Supporting Schedules'!G18,'Supporting Schedules'!C18:E18) -> 0.021386849 | C47: Debt Schedule | D47: Due to time constraints and limited information available on the cost of financing for Saia, Inc. (including no mentions in recent earnings calls), the debt schedule models interest assuming the composition of debt remains constant
B48: - | C48: Balance Sheet | D48: Wages and benefits payable expected to remain in line with inflation
B49: - | C49: Balance Sheet | D49: Given a fairly constant balance sheet, most current asset and current liability line items are treated as constant
B50: 300000 | C50: Balance Sheet | D50: Saia has historically maintained very low cash levels, primarily utilising it to expand their PP&E. Given this, the model assumes future cash will be efficiently used in debt paydowns, and, once the company matures, go towards buybacks and special dividends for capital structure optimisation. A ceiling will be imposed on cash to reflect this
...

Sheet BS
B3: Year Ended ($ thousands) | C3: 2020 | D3: 2021 | E3: 2022 | F3: 2023 | G3: 2024 | H3: 2025 | I3: 2026 | J3: 2027 | K3: 2028 | L3: 2029
B5: Current Assets
B6: Cash and cash equivalents | C6: 25308 | D6: 106588 | E6: 187390 | F6: 296215 | G6: 19473 | H6: =IF(CF!H40>'Inputs & Assumptions'!$B$50,'Inputs & Assumptions'!$B$50,CF!H40) -> 27890.467 | I6: =IF(CF!I40>'Inputs & Assumptions'!$B$50,'Inputs & Assumptions'!$B$50,CF!I40) -> 209918.55 | J6: =IF(CF!J40>'Inputs & Assumptions'!$B$50,'Inputs & Assumptions'!$B$50,CF!J40) -> 300000 | K6: =IF(CF!K40>'Inputs & Assumptions'!$B$50,'Inputs & Assumptions'!$B$50,CF!K40) -> 300000 | L6: =IF(CF!L40>'Inputs & Assumptions'!$B$50,'Inputs & Assumptions'!$B$50,CF!L40) -> 300000
B7: Accounts receivable, less allowances of $4,224 in 2024 and $4,427 in 2023 | C7: 216899 | D7: 276755 | E7: 290306 | F7: 311742 | G7: 322991 | H7: =$H$47*IS!H5/365 -> 387708.79 | I7: =$H$47*IS!I5/365 -> 423708.21 | J7: =$H$47*IS!J5/365 -> 463050.23 | K7: =$H$47*IS!K5/365 -> 506045.22 | L7: =$H$47*IS!L5/365 -> 553032.38
B8: Prepaid expenses | C8: 19505 | D8: 20329 | E8: 22525 | F8: 32648 | G8: 35497 | H8: 30000 | I8: 30000 | J8: 30000 | K8: 30000 | L8: 30000
B9: Income tax receivable | C9: 96 | D9: 0 | E9: 23438 | F9: 1005 | G9: 44107 | H9: 0 | I9: 0 | J9: 0 | K9: 0 | L9: 0
B10: Other current assets | C10: 9888 | D10: 12583 | E10: 7227 | F10: 7084 | G10: 13701 | H10: 10000 | I10: 10000 | J10: 10000 | K10: 10000 | L10: 10000
B11: Total current assets | C11: 271696 | D11: 416255 | E11: 530886 | F11: 648694 | G11: 435769 | H11: =SUM(H6:H10) -> 455599.26 | I11: =SUM(I6:I10) -> 673626.76 | J11: =SUM(J6:J10) -> 803050.23 | K11: =SUM(K6:K10) -> 846045.22 | L11: =SUM(L6:L10) -> 893032.38
B13: Property and Equipment, at cost | C13: 1901244 | D13: 2144528 | E13: 2478824 | F13: 2881800 | G13: 3790069
B14: Less-accumulated depreciation and amortization | C14: 765217 | D14: 864074 | E14: 996204 | F14: 1118492 | G14: 1233134
B15: Net property and equipment | C15: 1136027 | D15: 1280454 | E15: 1482620 | F15: 1763308 | G15: 2556935
B16: Operating Lease Right-of-Use Assets | C16: 113715 | D16: 107781 | E16: 120455 | F16: 118734 | G16: 126828
B17: Goodwill and Identifiable Intangibles, net | C17: =12105+8216 -> 20321 | D17: 19157 | E17: 18149 | F17: 17296 | G17: 16442
B18: Other Noncurrent Assets | C18: 7015 | D18: 21603 | E18: 22600 | F18: 35533 | G18: 30883
B19: Total assets | C19: 1548774 | D19: 1845250 | E19: 2174710 | F19: 2583565 | G19: 3166857
B21: Current Liabilities
B22: Accounts payable | C22: 89381 | D22: 114010 | E22: 99792 | F22: 141877 | G22: 114560 | H22: =$H$48*IS!H5/365 -> 153986.78 | I22: =$H$48*IS!I5/365 -> 168284.71 | J22: =$H$48*IS!J5/365 -> 183910.23 | K22: =$H$48*IS!K5/365 -> 200986.61 | L22: =$H$48*IS!L5/365 -> 219648.55
B23: Wages, vacation and employees’ benefits | C23: 55392 | D23: 73109 | E23: 66684 | F23: 75514 | G23: 49953 | H23: =AVERAGE($C$23:$G$23)*(1+_xlfn.XLOOKUP('Inputs & Assumptions'!$D$5,'Inputs & Assumptions'!$B$22:$B$24,'Inputs & Assumptions'!$E$22:$E$24,'Inputs & Assumptions'!$E$22)) -> 66118.442 | I23: =H23*(1+_xlfn.XLOOKUP('Inputs & Assumptions'!$D$5,'Inputs & Assumptions'!$B$22:$B$24,'Inputs & Assumptions'!$F$22:$F$24)) -> 68234.233 | J23: =I23*(1+_xlfn.XLOOKUP('Inputs & Assumptions'!$D$5,'Inputs & Assumptions'!$B$22:$B$24,'Inputs & Assumptions'!$F$22:$F$24)) -> 70417.728 | K23: =J23*(1+_xlfn.XLOOKUP('Inputs & Assumptions'!$D$5,'Inputs & Assumptions'!$B$22:$B$24,'Inputs & Assumptions'!$F$22:$F$24)) -> 72671.095 | L23: =K23*(1+_xlfn.XLOOKUP('Inputs & Assumptions'!$D$5,'Inputs & Assumptions'!$B$22:$B$24,'Inputs & Assumptions'!$F$22:$F$24)) -> 74996.57
B24: Claims and insurance accruals | C24: 49613 | D24: 54717 | E24: 45481 | F24: 41641 | G24: 43126 | H24: 45000 | I24: 45000 | J24: 45000 | K24: 45000 | L24: 45000
B25: Other current liabilities | C25: 40571 | D25: 38551 | E25: 22684 | F25: 27094 | G25: 38036 | H25: 30000 | I25: 30000 | J25: 30000 | K25: 30000 | L25: 30000
B26: Current portion of long-term debt | C26: 20588 | D26: 19396 | E26: 14519 | F26: 10173 | G26: 5313 | H26: 10000 | I26: 10000 | J26: 10000 | K26: 10000 | L26: 10000
B27: Current portion of operating lease liability | C27: 20209 | D27: 21565 | E27: 24925 | F27: 25757 | G27: 27372 | H27: 25000 | I27: 25000 | J27: 25000 | K27: 25000 | L27: 25000
B28: Total current liabilities | C28: 275754 | D28: 321348 | E28: 274085 | F28: 322056 | G28: 278360 | H28: =SUM(H22:H27) -> 330105.22 | I28: =SUM(I22:I27) -> 346518.95 | J28: =SUM(J22:J27) -> 364327.96 | K28: =SUM(K22:K27) -> 383657.7 | L28: =SUM(L22:L27) -> 404645.12
B30: Long-term debt, less current portion | C30: 50388 | D30: 31008 | E30: 16489 | F30: 6315 | G30: 194981
B31: Operating lease liability, less current portion | C31: 95321 | D31: 88409 | E31: 98581 | F31: 96462 | G31: 96798
B32: Deferred income taxes | C32: 119818 | D32: 124137 | E32: 145771 | F32: 155841 | G32: 219062
B33: Claims, insurance and other | C33: 46205 | D33: 60015 | E33: 60443 | F33: 61397 | G33: 66385
B34: Total liabilities | C34: =SUM(C28,C30:C33) -> 587486 | D34: =SUM(D28,D30:D33) -> 624917 | E34: =SUM(E28,E30:E33) -> 595369 | F34: =SUM(F28,F30:F33) -> 642071 | G34: =SUM(G28,G30:G33) -> 855586
B36: Stockholders’ Equity
B37: Preferred stock, $0.001 par value, 50,000 shares authorized, none issued and outstanding | C37: 0 | D37: 0 | E37: 0 | F37: 0 | G37: 0
B38: Common stock, $0.001 par value, 100,000,000 shares authorized, 26,549,512 and 26,4549,372 shares issued and outstanding at December 31, 2024 and 2023, respectively | C38: 26 | D38: 26 | E38: 26 | F38: 27 | G38: 27
B39: Additional paid-in-capital | C39: 267666 | D39: 274633 | E39: 277366 | F39: 285092 | G39: 295106
B40: Deferred compensation trust, 70,100 and 69,672 shares of common stock at cost at December 31, 2024 and 2023, respectively | C40: -2944 | D40: -4101 | E40: -5248 | F40: -5679 | G40: -7981
B41: Retained earnings | C41: 696540 | D41: 949775 | E41: 1307197 | F41: 1662054 | G41: 2024119
B42: Total stockholders’ equity | C42: 961288 | D42: 1220333 | E42: 1579341 | F42: 1941494 | G42: 2311271
B44: Total liabilities and stockholders’ equity | C44: 1548774 | D44: 1845250 | E44: 2174710 | F44: 2583565 | G44: 3166857
H46: Average
B47: Days Sales Outstanding | C47: =C7*365/IS!C5 -> 43.4425 | D47: =D7*365/IS!D5 -> 44.136583 | E47: =E7*365/IS!E5 -> 37.95112 | F47: =F7*365/IS!F5 -> 39.48932 | G47: =G7*365/IS!G5 -> 36.736989 | H47: =AVERAGE(C47:G47) -> 40.351302
B48: Days Payable Outstanding | C48: =C22*365/IS!C5 -> 17.902038 | D48: =D22*365/IS!D5 -> 18.18219 | E48: =E22*365/IS!E5 -> 13.045608 | F48: =F22*365/IS!F5 -> 17.971997 | G48: =G22*365/IS!G5 -> 13.030052 | H48: =AVERAGE(C48:G48) -> 16.026377

Sheet IS
B3: FY (in $ thousands) | C3: 2020 | D3: 2021 | E3: 2022 | F3: 2023 | G3: 2024 | H3: 2025 | I3: 2026 | J3: 2027 | K3: 2028 | L3: 2029
B5: Operating Revenue | C5: 1822366 | D5: 2288704 | E5: 2792057 | F5: 2881433 | G5: 3209074 | H5: =G5*(1+H6) -> 3507041.9 | I5: =H5*(1+I6) -> 3832676.7 | J5: =I5*(1+J6) -> 4188547.2 | K5: =J5*(1+K6) -> 4577460.8 | L5: =K5*(1+L6) -> 5002485.8
B6: % Change | D6: =D5/C5 - 1 -> 0.255897 | E6: =E5/D5 - 1 -> 0.21992927 | F6: =F5/E5 - 1 -> 0.032010808 | G6: =G5/F5 - 1 -> 0.11370766 | H6: =IF('Inputs & Assumptions'!$D$4<>5,_xlfn.XLOOKUP('Inputs & Assumptions'!$D$4,'Inputs & Assumptions'!$B$12:$B$17,'Inputs & Assumptions'!$D$12:$D$17,'Inputs & Assumptions'!$D$13),'Inputs & Assumptions'!$D$17*POWER(0.98,1+COLUMN(IS!H5)-COLUMNS(IS!$G$5))) -> 0.092851686 | I6: =IF('Inputs & Assumptions'!$D$4<>5,_xlfn.XLOOKUP('Inputs & Assumptions'!$D$4,'Inputs & Assumptions'!$B$12:$B$17,'Inputs & Assumptions'!$D$12:$D$17,'Inputs & Assumptions'!$D$13),'Inputs & Assumptions'!$D$17*POWER(0.98,1+COLUMN(IS!I5)-COLUMNS(IS!$G$5))) -> 0.092851686 | J6: =IF('Inputs & Assumptions'!$D$4<>5,_xlfn.XLOOKUP('Inputs & Assumptions'!$D$4,'Inputs & Assumptions'!$B$12:$B$17,'Inputs & Assumptions'!$D$12:$D$17,'Inputs & Assumptions'!$D$13),'Inputs & Assumptions'!$D$17*POWER(0.98,1+COLUMN(IS!J5)-COLUMNS(IS!$G$5))) -> 0.092851686 | K6: =IF('Inputs & Assumptions'!$D$4<>5,_xlfn.XLOOKUP('Inputs & Assumptions'!$D$4,'Inputs & Assumptions'!$B$12:$B$17,'Inputs & Assumptions'!$D$12:$D$17,'Inputs & Assumptions'!$D$13),'Inputs & Assumptions'!$D$17*POWER(0.98,1+COLUMN(IS!K5)-COLUMNS(IS!$G$5))) -> 0.092851686 | L6: =IF('Inputs & Assumptions'!$D$4<>5,_xlfn.XLOOKUP('Inputs & Assumptions'!$D$4,'Inputs & Assumptions'!$B$12:$B$17,'Inputs & Assumptions'!$D$12:$D$17,'Inputs & Assumptions'!$D$13),'Inputs & Assumptions'!$D$17*POWER(0.98,1+COLUMN(IS!L5)-COLUMNS(IS!$G$5))) -> 0.092851686
B8: Salaries, wages and employees’ benefits | C8: 963260 | D8: 1063703 | E8: 1169539 | F8: 1301280 | G8: 1487847 | H8: =H9*H5 -> 1593251.9 | I8: =I9*I5 -> 1741188 | J8: =J9*J5 -> 1902860.2 | K8: =K9*K5 -> 2079544 | L8: =L9*L5 -> 2272633.2
B9: % Revenue | C9: =C8/C5 -> 0.52857659 | D9: =D8/D5 -> 0.46476215 | E9: =E8/E5 -> 0.41888077 | F9: =F8/F5 -> 0.45160863 | G9: =G8/G5 -> 0.46363749 | H9: ='Inputs & Assumptions'!$B$36 -> 0.45430077 | I9: ='Inputs & Assumptions'!$B$36 -> 0.45430077 | J9: ='Inputs & Assumptions'!$B$36 -> 0.45430077 | K9: ='Inputs & Assumptions'!$B$36 -> 0.45430077 | L9: ='Inputs & Assumptions'!$B$36 -> 0.45430077
B10: Purchased transportation | C10: 141369 | D10: 249710 | E10: 315896 | F10: 238688 | G10: 237306 | H10: =G10*(1+H11) -> 225440.7 | I10: =H10*(1+I11) -> 214168.66 | J10: =I10*(1+J11) -> 203460.23 | K10: =J10*(1+K11) -> 193287.22 | L10: =K10*(1+L11) -> 183622.86
B11: % Change | D11: =D10/C10-1 -> 0.76637028 | E11: =E10/D10-1 -> 0.26505146 | F11: =F10/E10-1 -> -0.24440955 | G11: =G10/F10-1 -> -0.0057899853 | H11: ='Inputs & Assumptions'!$B$37 -> -0.05 | I11: ='Inputs & Assumptions'!$B$37 -> -0.05 | J11: ='Inputs & Assumptions'!$B$37 -> -0.05 | K11: ='Inputs & Assumptions'!$B$37 -> -0.05 | L11: ='Inputs & Assumptions'!$B$37 -> -0.05
B12: Fuel, operating expenses and supplies | C12: 299234 | D12: 381904 | E12: 558456 | F12: 563688 | G12: 629402 | H12: =H13*H5 -> 644907.77 | I12: =I13*I5 -> 704788.54 | J12: =J13*J5 -> 770229.34 | K12: =K13*K5 -> 841746.44 | L12: =L13*L5 -> 919904.01
B13: % Revenue | C13: =C12/C5 -> 0.16420082 | D13: =D12/D5 -> 0.16686474 | E13: =E12/E5 -> 0.20001597 | F13: =F12/F5 -> 0.19562766 | G13: =G12/G5 -> 0.19613197 | H13: =GEOMEAN($C$13:$G$13) -> 0.18388938 | I13: =GEOMEAN($C$13:$G$13) -> 0.18388938 | J13: =GEOMEAN($C$13:$G$13) -> 0.18388938 | K13: =GEOMEAN($C$13:$G$13) -> 0.18388938 | L13: =GEOMEAN($C$13:$G$13) -> 0.18388938
B14: Operating taxes and licenses | C14: 56294 | D14: 59095 | E14: 63824 | F14: 69542 | G14: 80128 | H14: =H15*H5 -> 89767.488 | I14: =I15*I5 -> 98102.551 | J14: =J15*J5 -> 107211.54 | K14: =K15*K5 -> 117166.31 | L14: =L15*L5 -> 128045.4
B15: % Revenue | C15: =C14/C5 -> 0.030890611 | D15: =D14/D5 -> 0.02582029 | E15: =E14/E5 -> 0.022859132 | F15: =F14/F5 -> 0.024134519 | G15: =G14/G5 -> 0.024969197 | H15: =GEOMEAN($C$15:$G$15) -> 0.025596354 | I15: =GEOMEAN($C$15:$G$15) -> 0.025596354 | J15: =GEOMEAN($C$15:$G$15) -> 0.025596354 | K15: =GEOMEAN($C$15:$G$15) -> 0.025596354 | L15: =GEOMEAN($C$15:$G$15) -> 0.025596354
B16: Claims and insurance | C16: 49761 | D16: 61345 | E16: 56601 | F16: 67984 | G16: 77649 | H16: =H17*H5 -> 85215.853 | I16: =I17*I5 -> 93128.289 | J16: =J17*J5 -> 101775.41 | K16: =K17*K5 -> 111225.43 | L16: =L17*L5 -> 121552.89
B17: % Revenue | C17: =C16/C5 -> 0.027305711 | D17: =D16/D5 -> 0.026803379 | E17: =E16/E5 -> 0.020272151 | F17: =F16/F5 -> 0.023593816 | G17: =G16/G5 -> 0.0241967 | H17: =GEOMEAN($C$17:$G$17) -> 0.024298498 | I17: =GEOMEAN($C$17:$G$17) -> 0.024298498 | J17: =GEOMEAN($C$17:$G$17) -> 0.024298498 | K17: =GEOMEAN($C$17:$G$17) -> 0.024298498 | L17: =GEOMEAN($C$17:$G$17) -> 0.024298498
B18: COGS | C18: =SUM(C8:C16) -> 1509918.7 | D18: =SUM(D8:D16) -> 1815758.4 | E18: =SUM(E8:E16) -> 2164316.9 | F18: =SUM(F8:F16) -> 2241182.4 | G18: =SUM(G8:G16) -> 2512332.7 | H18: =SUM(H16,H14,H12,H10,H8) -> 2638583.7 | I18: =SUM(I16,I14,I12,I10,I8) -> 2851376 | J18: =SUM(J16,J14,J12,J10,J8) -> 3085536.7 | K18: =SUM(K16,K14,K12,K10,K8) -> 3342969.4 | L18: =SUM(L16,L14,L12,L10,L8) -> 3625758.3
B19: % Revenue | C19: =C18/C5 -> 0.82854856 | D19: =D18/D5 -> 0.7933566 | E19: =E18/E5 -> 0.77516931 | F19: =F18/F5 -> 0.77780133 | G19: =G18/G5 -> 0.782884 | H19: =H18/H5 -> 0.7523673 | I19: =I18/I5 -> 0.74396466 | J19: =J18/J5 -> 0.73666037 | ... L19: =L18/L5 -> 0.72479133
B21: Depreciation and amortization | C21: 134655 | D21: 141700 | E21: 157203 | F21: 178845 | G21: 210105 | H21: =H22*H5 -> 361216.98 | I21: =I22*I5 -> 394756.59 | J21: =J22*J5 -> 431410.4 | K21: =K22*K5 -> 471467.58 | L21: =L22*L5 -> 515244.14
B22: % PP&E | C22: =C21/BS!C15 -> 0.11853151 | D22: =D21/BS!D15 -> 0.11066387 | E22: =E21/BS!E15 -> 0.10603054 | F22: =F21/BS!F15 -> 0.10142584 | G22: =G21/BS!G15 -> 0.082170646 | H22: ='Inputs & Assumptions'!$B$41 -> 0.10299762 | I22: ='Inputs & Assumptions'!$B$41 -> 0.10299762 | J22: ='Inputs & Assumptions'!$B$41 -> 0.10299762 | K22: ='Inputs & Assumptions'!$B$41 -> 0.10299762 | L22: ='Inputs & Assumptions'!$B$41 -> 0.10299762
B23: Operating losses, net | C23: -2528 | D23: -3894 | E23: 50 | F23: 910 | G23: 4477 | H23: 0 | I23: 0 | J23: 0 | K23: 0 | L23: 0
B24: Total operating expenses | C24: 1642045 | D24: 1953563 | E24: 2321569 | F24: 2420937 | G24: 2726914 | H24: =H21+H18 -> 2999800.6 | I24: =I21+I18 -> 3246132.6 | J24: =J21+J18 -> 3516947.1 | K24: =K21+K18 -> 3814437 | L24: =L21+L18 -> 4141002.5
B25: Operating Income (EBIT) | C25: 180321 | D25: 335141 | E25: 470488 | F25: 460496 | G25: 482160 | H25: =H5-H24 -> 507241.29 | I25: =I5-I24 -> 586544.08 | J25: =J5-J24 -> 671600.05 | K25: =K5-K24 -> 763023.88 | L25: =L5-L24 -> 861483.34
B27: Non-operating (Income) Expenses
B28: Interest expense | C28: 5177 | D28: 3212 | E28: 2611 | F28: 2535 | G28: 8930 | H28: ='Supporting Schedules'!H17 -> 6601.2007 | I28: ='Supporting Schedules'!I17 -> 6263.1388 | J28: ='Supporting Schedules'!J17 -> 5925.0768 | K28: ='Supporting Schedules'!K17 -> 5587.0149 | L28: ='Supporting Schedules'!L17 -> 5248.953
B29: Interest income | E29: -217 | F29: -6208 | G29: -1049 | H29: 0 | I29: 0 | J29: 0 | K29: 0 | L29: 0
B30: Other, net | C30: -1134 | D30: -844 | E30: 46 | F30: -2058 | G30: -1729 | H30: 0 | I30: 0 | J30: 0 | K30: 0 | L30: 0
B31: Non-operating (income) expenses, net | C31: 4043 | D31: 2368 | E31: 2440 | F31: -5731 | G31: 6152 | H31: 0 | I31: 0 | J31: 0 | K31: 0 | L31: 0
B32: Income Before Income Taxes (EBT) | C32: 176278 | D32: 332773 | E32: 468048 | F32: 466227 | G32: 476008 | H32: =H25-H28 -> 500640.09 | I32: =I25-I28 -> 580280.95 | J32: =J25-J28 -> 665674.97 | K32: =K25-K28 -> 757436.86 | L32: =L25-L28 -> 856234.39
B33: Implied Tax Rate | C33: =C34/C32 -> 0.21521687 | D33: =D34/D32 -> 0.23901579 | E33: =E34/E32 -> 0.2363561 | F33: =F34/F32 -> 0.23887505 | G33: =G34/G32 -> 0.23937203 | H33: ='Inputs & Assumptions'!$B$42 -> 0.23357308 | I33: ='Inputs & Assumptions'!$B$42 -> 0.23357308 | J33: ='Inputs & Assumptions'!$B$42 -> 0.23357308 | K33: ='Inputs & Assumptions'!$B$42 -> 0.23357308 | L33: ='Inputs & Assumptions'!$B$42 -> 0.23357308
B34: Income Tax Expense | C34: 37938 | D34: 79538 | E34: 110626 | F34: 111370 | G34: 113943 | H34: =H33*H32 -> 116936.05 | I34: =I33*I32 -> 135538.01 | J34: =J33*J32 -> 155483.75 | K34: =K33*K32 -> 176916.86 | L34: =L33*L32 -> 199993.3
B36: Net Income | C36: 138340 | D36: 253235 | E36: 357422 | F36: 354857 | G36: 362065 | H36: =H32-H34 -> 383704.04 | I36: =I32-I34 -> 444742.94 | J36: =J32-J34 -> 510191.22 | K36: =K32-K34 -> 580520.01 | L36: =L32-L34 -> 656241.09
B38: EBITDA | C38: =C25+C21 -> 314976 | D38: =D25+D21 -> 476841 | E38: =E25+E21 -> 627691 | F38: =F25+F21 -> 639341 | G38: =G25+G21 -> 692265 | H38: =H25+H21 -> 868458.27 | I38: =I25+I21 -> 981300.67 | J38: =J25+J21 -> 1103010.4 | ... L38: =L25+L21 -> 1376727.5
B39: % Growth | D39: =D38/C38-1 -> 0.5138963 | E39: =E38/D38-1 -> 0.31635283 | F39: =F38/E38-1 -> 0.018560088 | G39: =G38/F38-1 -> 0.082778986 | H39: =H38/G38-1 -> 0.25451709 | I39: =I38/H38-1 -> 0.12993416 | J39: =J38/I38-1 -> 0.12402904 | K39: =K38/J38-1 -> 0.11920197 | L39: =L38/K38-1 -> 0.11521831
B40: Weighted average common shares outstanding – basic | C40: 26140 | D40: 26322 | E40: 26520 | F40: 26632 | G40: 26689
B41: Basic Earnings Per Share | C41: 5.29 | D41: 9.62 | E41: 13.48 | F41: 13.32 | G41: 13.57
B42: Weighted average common shares outstanding – diluted | C42: 26592 | D42: 26707 | E42: 26674 | F42: 26763 | G42: 26802 | H42: =G42*(1+H43) -> 26854.819 | I42: =H42*(1+I43) -> 26907.741 | J42: =I42*(1+J43) -> 26960.768 | K42: =J42*(1+K43) -> 27013.9 | L42: =K42*(1+L43) -> 27067.136
B43: % Growth | D43: =D42/C42-1 -> 0.0043246089 | E43: =E42/D42-1 -> -0.0012356311 | F43: =F42/E42-1 -> 0.0033365824 | G43: =G42/F42-1 -> 0.0014572357 | H43: ='Inputs & Assumptions'!$B$40 -> 0.001970699 | I43: ='Inputs & Assumptions'!$B$40 -> 0.001970699 | J43: ='Inputs & Assumptions'!$B$40 -> 0.001970699 | K43: ='Inputs & Assumptions'!$B$40 -> 0.001970699 | L43: ='Inputs & Assumptions'!$B$40 -> 0.001970699
B44: Diluted Earnings Per Share | C44: 5.2 | D44: 9.48 | E44: 13.4 | F44: 13.26 | G44: 13.51 | H44: =H36/H42 -> 14.288089 | I44: =I36/I42 -> 16.528438 | J44: =J36/J42 -> 18.923467 | K44: =K36/K42 -> 21.489678 | L44: =L36/L42 -> 24.24494
B45: % Growth | D45: =D44/C44-1 -> 0.82307692 | E45: =E44/D44-1 -> 0.41350211 | F45: =F44/E44-1 -> -0.010447761 | G45: =G44/F44-1 -> 0.018853695 | H45: =H44/G44-1 -> 0.057593572 | I45: =I44/H44-1 -> 0.15679836 | J45: =J44/I44-1 -> 0.14490353 | K45: =K44/J44-1 -> 0.13560995 | L45: =L44/K44-1 -> 0.12821327
B47: Trailing P/E | C47: 34.18 | D47: 35.03 | E47: 15.55 | F47: 32.9 | G47: 33.58
B48: Forward P/E | H48: =DCF!$C$24/H44 -> 20.172746 | I48: =DCF!$C$24/I44 -> 17.438429 | J48: =DCF!$C$24/J44 -> 15.231353 | K48: =DCF!$C$24/K44 -> 13.412486 | L48: =DCF!$C$24/L44 -> 11.888254
B49: PEG Ratio | D49: =(D48+D47)/(D45*100) -> 0.42559813 | E49: =(E48+E47)/(E45*100) -> 0.37605612 | F49: =(F48+F47)/(F45*100) -> -31.49 | G49: =(G48+G47)/(G45*100) -> 17.810832 | H49: =(H48+H47)/(H45*100) -> 3.5026038 | I49: =(I48+I47)/(I45*100) -> 1.1121564 | J49: =(J48+J47)/(J45*100) -> 1.0511374 | K49: =(K48+K47)/(K45*100) -> 0.98904878 | L49: =(L48+L47)/(L45*100) -> 0.92722491

Sheet CF
B3: FY (in $ thousands) | C3: 2020 | D3: 2021 | E3: 2022 | F3: 2023 | G3: 2024 | H3: 2025 | I3: 2026 | J3: 2027 | K3: 2028 | L3: 2029
B5: Operating Activities
B6: Net income | C6: 138340 | D6: 253235 | E6: 357422 | F6: 354857 | G6: 362065 | H6: =IS!H36 -> 383704.04 | I6: =IS!I36 -> 444742.94 | J6: =IS!J36 -> 510191.22 | K6: =IS!K36 -> 580520.01 | L6: =IS!L36 -> 656241.09
B8: Noncash items included in net income
B9: Depreciation and amortization | C9: 134655 | D9: 141700 | E9: 157203 | F9: 178845 | G9: 210105 | H9: =IS!H21 -> 361216.98 | I9: =IS!I21 -> 394756.59 | J9: =IS!J21 -> 431410.4 | K9: =IS!K21 -> 471467.58 | L9: =IS!L21 -> 515244.14
B10: Allowance for credit losses | C10: 4271 | D10: 3559 | E10: 3074 | F10: 1955 | G10: 3412 | H10: 3000 | I10: 3000 | J10: 3000 | K10: 3000 | L10: 3000
B11: Deferred income taxes | C11: 8263 | D11: 4319 | E11: 21634 | F11: 10070 | G11: 63221 | H11: 10000 | I11: 10000 | J11: 10000 | K11: 10000 | L11: 10000
B12: Loss from property disposals, net | C12: -2528 | D12: -3894 | E12: 50 | F12: 910 | G12: 4477 | H12: 0 | I12: 0 | J12: 0 | K12: 0 | L12: 0
B13: Stock-based compensation | C13: 7536 | D13: 8703 | E13: 8827 | F13: 11636 | G13: 14243 | H13: 15000 | I13: 15000 | J13: 15000 | K13: 15000 | L13: 15000
B15: Changes in operating assets and liabilities
B16: Accounts receivable | C16: -25051 | D16: -63415 | E16: -16624 | F16: -23391 | G16: -14661 | H16: =BS!G7-BS!H7 -> -64717.793 | I16: =BS!H7-BS!I7 -> -35999.415 | J16: =BS!I7-BS!J7 -> -39342.022 | K16: =BS!J7-BS!K7 -> -42994.995 | L16: =BS!K7-BS!L7 -> -46987.152
B17: Accounts payable | C17: 5772 | D17: 16729 | E17: -9523 | F17: 10752 | G17: -816 | H17: =BS!H22-BS!G22 -> 39426.781 | I17: =BS!I22-BS!H22 -> 14297.932 | J17: =BS!J22-BS!I22 -> 15625.519 | K17: =BS!K22-BS!J22 -> 17076.375 | L17: =BS!L22-BS!K22 -> 18661.945
B18: Change in other assets and liabilities, net | C18: 37887 | D18: -21656 | E18: -49037 | F18: 32311 | G18: -58344 | H18: 0 | I18: 0 | J18: 0 | K18: 0 | L18: 0
B19: Net cash provided by operating activities | C19: 309145 | D19: 382592 | E19: 473026 | F19: 577945 | G19: 583702 | H19: =SUM(H6:H18) -> 747630.01 | I19: =SUM(I6:I18) -> 845798.04 | J19: =SUM(J6:J18) -> 945885.12 | K19: =SUM(K6:K18) -> 1054069 | L19: =SUM(L6:L18) -> 1171160
B21: Investing Activities
B22: Acquisition of property and equipment | C22: -231142 | D22: -285746 | E22: -367429 | F22: -439879 | G22: -1043557 | H22: =-'Supporting Schedules'!H5 -> -600000 | I22: =-'Supporting Schedules'!I5 -> -511863.42 | J22: =-'Supporting Schedules'!J5 -> -559390.81 | K22: =-'Supporting Schedules'!K5 -> -611331.18 | L22: =-'Supporting Schedules'!L5 -> -668094.32
B23: Proceeds from disposal of property and equipment | C23: 12325 | D23: 8398 | E23: 1917 | F23: 2727 | G23: 2694 | H23: 2500 | I23: 2500 | J23: 2500 | K23: 2500 | L23: 2500
B24: Other | C24: 0 | D24: -500 | E24: 0 | F24: -11544 | G24: 4999 | H24: 0 | I24: 0 | J24: 0 | K24: 0 | L24: 0
B25: Net cash used in investing activities | C25: -218817 | D25: -277848 | E25: -365512 | F25: -448696 | G25: -1035864 | H25: =H22-H23-H24 -> -602500 | I25: =I22-I23-I24 -> -514363.42 | J25: =J22-J23-J24 -> -561890.81 | K25: =K22-K23-K24 -> -613831.18 | L25: =L22-L23-L24 -> -670594.32
B27: Financing Activities
B28: Repayments of revolving credit facility | C28: -369001 | D28: -43175 | E28: -1000 | F28: 0 | G28: -1060100
B29: Borrowings of revolving credit facility | C29: 323072 | D29: 43175 | E29: 1000 | F29: 0 | G29: 1154100
B30: Borrowings on private shelf agreement | C30: 0 | D30: 0 | E30: 0 | F30: 0 | G30: 100000
B31: Proceeds from stock option exercises | C31: 3786 | D31: 3678 | E31: 4511 | F31: 4875 | G31: 2574
B32: Shares withheld for taxes | C32: -3600 | D32: -6571 | E32: -11752 | F32: -9216 | G32: -9107
B33: Repayment of finance leases | C33: -19525 | D33: -20571 | E33: -19471 | F33: -14520 | G33: -10193
B34: Other financing activity | E34: 0 | F34: -1563 | G34: -1854
B35: Net cash (used in) provided by financing activities | C35: -65268 | D35: -23464 | E35: -26712 | F35: -20424 | G35: 175420 | H35: =H36*IS!H5 -> -136712.55 | I35: =I36*IS!I5 -> -149406.54 | J35: =J36*IS!J5 -> -163279.18 | K35: =K36*IS!K5 -> -178439.93 | L35: =L36*IS!L5 -> -195008.38
B36: % 2x Current Liabilities | C36: =C35/(2*BS!C28) -> -0.11834461 | D36: =D35/(2*BS!D28) -> -0.036508707 | E36: =E35/(2*BS!E28) -> -0.048729409 | F36: =F35/(2*BS!F28) -> -0.031708771 | G36: =G35/(2*BS!G28) -> 0.31509556 | H36: ='Inputs & Assumptions'!$B$52 -> -0.038982296 | I36: ='Inputs & Assumptions'!$B$52 -> -0.038982296 | J36: ='Inputs & Assumptions'!$B$52 -> -0.038982296 | K36: ='Inputs & Assumptions'!$B$52 -> -0.038982296 | L36: ='Inputs & Assumptions'!$B$52 -> -0.038982296
B38: Net Increase (Decrease) in Cash and Cash Equivalents | C38: 25060 | D38: 81280 | E38: 80802 | F38: 108825 | G38: -276742 | H38: =SUM(H35,H25,H19) -> 8417.4669 | I38: =SUM(I35,I25,I19) -> 182028.08 | J38: =SUM(J35,J25,J19) -> 220715.13 | K38: =SUM(K35,K25,K19) -> 261797.85 | L38: =SUM(L35,L25,L19) -> 305557.33
B39: Cash and cash equivalents, beginning of year | C39: 248 | D39: 25308 | E39: 106588 | F39: 187390 | G39: 296215 | H39: =G40 -> 19473 | I39: =H40 -> 27890.467 | J39: =I40 -> 209918.55 | K39: =J40 -> 430633.68 | L39: =K40 -> 692431.53
B40: Cash and cash equivalents, end of year | C40: 25308 | D40: 106588 | E40: 187390 | F40: 296215 | G40: 19473 | H40: =H39+H38 -> 27890.467 | I40: =I39+I38 -> 209918.55 | J40: =J39+J38 -> 430633.68 | K40: =K39+K38 -> 692431.53 | L40: =L39+L38 -> 997988.86

Sheet DCF
B3: FY (in $ thousands) | C3: 2020 | D3: 2021 | E3: 2022 | F3: 2023 | G3: 2024 | H3: 2025 | I3: 2026 | J3: 2027 | K3: 2028 | L3: 2029
B5: EBIT | C5: =IS!C25 -> 180321 | D5: =IS!D25 -> 335141 | E5: =IS!E25 -> 470488 | F5: =IS!F25 -> 460496 | G5: =IS!G25 -> 482160 | H5: =IS!H25 -> 507241.29 | I5: =IS!I25 -> 586544.08 | J5: =IS!J25 -> 671600.05 | ... L5: =IS!L25 -> 861483.34
B6: NOPAT | C6: =C5*(1-'Inputs & Assumptions'!$B$42) -> 138202.87 | D6: =D5*(1-'Inputs & Assumptions'!$B$42) -> 256861.09 | E6: =E5*(1-'Inputs & Assumptions'!$B$42) -> 360594.67 | F6: =F5*(1-'Inputs & Assumptions'!$B$42) -> 352936.53 | G6: =G5*(1-'Inputs & Assumptions'!$B$42) -> 369540.4 | H6: =H5*(1-'Inputs & Assumptions'!$B$42) -> 388763.38 | I6: =I5*(1-'Inputs & Assumptions'!$B$42) -> 449543.18 | J6: =J5*(1-'Inputs & Assumptions'!$B$42) -> 514732.36 | ... L6: =L5*(1-'Inputs & Assumptions'!$B$42) -> 660264.02
B7: (CapEx) | C7: ='Supporting Schedules'!C5 -> 231142 | D7: ='Supporting Schedules'!D5 -> 285746 | E7: ='Supporting Schedules'!E5 -> 367429 | F7: ='Supporting Schedules'!F5 -> 439879 | G7: ='Supporting Schedules'!G5 -> 1043557 | H7: ='Supporting Schedules'!H5 -> 600000 | I7: ='Supporting Schedules'!I5 -> 511863.42 | J7: ='Supporting Schedules'!J5 -> 559390.81 | ... L7: ='Supporting Schedules'!L5 -> 668094.32
B8: D&A | C8: =IS!C21 -> 134655 | D8: =IS!D21 -> 141700 | E8: =IS!E21 -> 157203 | F8: =IS!F21 -> 178845 | G8: =IS!G21 -> 210105 | H8: =IS!H21 -> 361216.98 | I8: =IS!I21 -> 394756.59 | J8: =IS!J21 -> 431410.4 | ... L8: =IS!L21 -> 515244.14
B9: Net Working Capital | C9: =SUM(BS!C7:C10)-SUM(BS!C22:C27) -> -29366 | D9: =SUM(BS!D7:D10)-SUM(BS!D22:D27) -> -11681 | E9: =SUM(BS!E7:E10)-SUM(BS!E22:E27) -> 69411 | F9: =SUM(BS!F7:F10)-SUM(BS!F22:F27) -> 30423 | G9: =SUM(BS!G7:G10)-SUM(BS!G22:G27) -> 137936 | H9: =SUM(BS!H7:H10)-SUM(BS!H22:H27) -> 97603.57 | I9: =SUM(BS!I7:I10)-SUM(BS!I22:I27) -> 117189.26 | J9: =SUM(BS!J7:J10)-SUM(BS!J22:J27) -> 138722.27 | ... L9: =SUM(BS!L7:L10)-SUM(BS!L22:L27) -> 188387.25
B10: Change | D10: =D9-C9 -> 17685 | E10: =E9-D9 -> 81092 | F10: =F9-E9 -> -38988 | G10: =G9-F9 -> 107513 | H10: =H9-G9 -> -40332.43 | I10: =I9-H9 -> 19585.693 | J10: =J9-I9 -> 21533.007 | K10: =K9-J9 -> 23665.252 | L10: =L9-K9 -> 25999.732
B12: FCFF | C12: =C6-DCF!C7+DCF!C8-DCF!C10 -> 41715.869 | D12: =D6-DCF!D7+DCF!D8-DCF!D10 -> 95130.085 | E12: =E6-DCF!E7+DCF!E8-DCF!E10 -> 69276.67 | F12: =F6-DCF!F7+DCF!F8-DCF!F10 -> 130890.53 | G12: =G6-DCF!G7+DCF!G8-DCF!G10 -> -571424.6 | H12: =H6-DCF!H7+DCF!H8-DCF!H10 -> 190312.79 | I12: =I6-DCF!I7+DCF!I8-DCF!I10 -> 312850.65 | J12: =J6-DCF!J7+DCF!J8-DCF!J10 -> 365218.95 | ... L12: =L6-DCF!L7+DCF!L8-DCF!L10 -> 481414.12
B13: PV(FCFF) | H13: =H12/POWER(1+$C$16,COLUMN(H12)-COLUMN($H$12)+1) -> 175458.73 | I13: =I12/POWER(1+$C$16,COLUMN(I12)-COLUMN($H$12)+1) -> 265920.04 | J13: =J12/POWER(1+$C$16,COLUMN(J12)-COLUMN($H$12)+1) -> 286203.08 | K13: =K12/POWER(1+$C$16,COLUMN(K12)-COLUMN($H$12)+1) -> 304362.98 | L13: =L12/POWER(1+$C$16,COLUMN(L12)-COLUMN($H$12)+1) -> 320666.68
B16: WACC | C16: =_xlfn.XLOOKUP('Inputs & Assumptions'!$D$6,'Inputs & Assumptions'!B29:B32,'Inputs & Assumptions'!C29:C32,'Inputs & Assumptions'!$C$29) -> 0.084658433
B17: Terminal Growth Rate | C17: ='Inputs & Assumptions'!$D$7 -> 0.03
B18: Terminal Value | C18: =L12*(1+C17)/(C16-C17) -> 9071912.9
B19: Enterprise Value | C19: =SUM(H13:L13,C18) -> 10424524
B21: Equity Value | C21: =C19-WACC!C13+BS!G6 -> 10108869
B22: Price Target | C22: =C21/IS!G42 -> 377.16847
B24: #VALUE! | C24: {=_FV(B24,"Previous close",TRUE)} -> 288.23
B25: Upside (%) | C25: =C22/C24 - 1 -> 0.30856772
B28: Sensitivity Analysis
B30: Revenue Growth | C30: Growth | D30: Price | E30: Return | H30: Switchboard Inputs | J30: Scenario | K30: Price | L30: Upside
C31: =C32-2.5% -> 0.042851686 | D31: 285.3 | E31: =D31/$C$24-1 -> -0.010165493 | J31: Worst | K31: 158.45 | L31: =K31/$C$24-1 -> -0.45026541
C32: =C33-2.5% -> 0.067851686 | D32: 329.4 | E32: =D32/$C$24-1 -> 0.14283732 | J32: Bear | K32: 297.43 | L32: =K32/$C$24-1 -> 0.031918954
C33: =_xlfn.XLOOKUP('Inputs & Assumptions'!$D$4,Table1[ID],Table1[CAGR],'Inputs & Assumptions'!$D$13) -> 0.092851686 | D33: =$C$22 -> 377.16847 | E33: =C25 -> 0.30856772 | J33: Base | K33: 377.17 | L33: =K33/C24-1 -> 0.30857301
C34: =C33+2.5% -> 0.11785169 | D34: 428.85 | E34: =D34/$C$24-1 -> 0.48787427 | J34: Bull | K34: 420 | L34: =K34/$C$24-1 -> 0.45716962
C35: =C34+2.5% -> 0.14285169 | D35: 484.67 | E35: =D35/$C$24-1 -> 0.68153905 | J35: Best | K35: 568.45 | L35: =K35/$C$24-1 -> 0.97220969
B37: Stock Price | C37: TGR/WACC | D37: =E37-0.001 -> 0.081658433 | E37: =F37-0.001 -> 0.082658433 | F37: =G37-0.001 -> 0.083658433 | G37: =_xlfn.XLOOKUP('Inputs & Assumptions'!$D$6,'Inputs & Assumptions'!$B$29:$B$32,'Inputs & Assumptions'!$C$29:$C$32,'Inputs & Assumptions'!$C$29) -> 0.084658433 | H37: =G37+0.001 -> 0.085658433 | I37: =H37+0.001 -> 0.086658433 | J37: =I37+0.001 -> 0.087658433 | K37: =J37+0.001 -> 0.088658433 | L37: =K37+0.001 -> 0.089658433
C38: =C39-0.05% -> 0.028 | D38: =(NPV(D$37,$H$12,$I$12,$J$12,$K$12,$L$12)+($L$12*(1+$C38)/(D$37-$C38))-WACC!$C$13+BS!$G$6)/IS!$G$42 -> 383.26273 | E38: =(NPV(E$37,$H$12,$I$12,$J$12,$K$12,$L$12)+($L$12*(1+$C38)/(E$37-$C38))-WACC!$C$13+BS!$G$6)/IS!$G$42 -> 376.81437 | F38: =(NPV(F$37,$H$12,$I$12,$J$12,$K$12,$L$12)+($L$12*(1+$C38)/(F$37-$C38))-WACC!$C$13+BS!$G$6)/IS!$G$42 -> 370.59291 | G38: =(NPV(G$37,$H$12,$I$12,$J$12,$K$12,$L$12)+($L$12*(1+$C38)/(G$37-$C38))-WACC!$C$13+BS!$G$6)/IS!$G$42 -> 364.58638 | H38: =(NPV(H$37,$H$12,$I$12,$J$12,$K$12,$L$12)+($L$12*(1+$C38)/(H$37-$C38))-WACC!$C$13+BS!$G$6)/IS!$G$42 -> 358.78362 | I38: =(NPV(I$37,$H$12,$I$12,$J$12,$K$12,$L$12)+($L$12*(1+$C38)/(I$37-$C38))-WACC!$C$13+BS!$G$6)/IS!$G$42 -> 353.17424 | J38: =(NPV(J$37,$H$12,$I$12,$J$12,$K$12,$L$12)+($L$12*(1+$C38)/(J$37-$C38))-WACC!$C$13+BS!$G$6)/IS!$G$42 -> 347.74855 | K38: =(NPV(K$37,$H$12,$I$12,$J$12,$K$12,$L$12)+($L$12*(1+$C38)/(K$37-$C38))-WACC!$C$13+BS!$G$6)/IS!$G$42 -> 342.49749 | L38: =(NPV(L$37,$H$12,$I$12,$J$12,$K$12,$L$12)+($L$12*(1+$C38)/(L$37-$C38))-WACC!$C$13+BS!$G$6)/IS!$G$42 -> 337.41259
C39: =C40-0.05% -> 0.0285 | D39: =(NPV(D$37,$H$12,$I$12,$J$12,$K$12,$L$12)+($L$12*(1+$C39)/(D$37-$C39))-WACC!$C$13+BS!$G$6)/IS!$G$42 -> 386.66839 | E39: =(NPV(E$37,$H$12,$I$12,$J$12,$K$12,$L$12)+($L$12*(1+$C39)/(E$37-$C39))-WACC!$C$13+BS!$G$6)/IS!$G$42 -> 380.09902 | F39: =(NPV(F$37,$H$12,$I$12,$J$12,$K$12,$L$12)+($L$12*(1+$C39)/(F$37-$C39))-WACC!$C$13+BS!$G$6)/IS!$G$42 -> 373.763 | G39: =(NPV(G$37,$H$12,$I$12,$J$12,$K$12,$L$12)+($L$12*(1+$C39)/(G$37-$C39))-WACC!$C$13+BS!$G$6)/IS!$G$42 -> 367.64789 | H39: =(NPV(H$37,$H$12,$I$12,$J$12,$K$12,$L$12)+($L$12*(1+$C39)/(H$37-$C39))-WACC!$C$13+BS!$G$6)/IS!$G$42 -> 361.74212 | I39: =(NPV(I$37,$H$12,$I$12,$J$12,$K$12,$L$12)+($L$12*(1+$C39)/(I$37-$C39))-WACC!$C$13+BS!$G$6)/IS!$G$42 -> 356.03494 | J39: =(NPV(J$37,$H$12,$I$12,$J$12,$K$12,$L$12)+($L$12*(1+$C39)/(J$37-$C39))-WACC!$C$13+BS!$G$6)/IS!$G$42 -> 350.51629 | K39: =(NPV(K$37,$H$12,$I$12,$J$12,$K$12,$L$12)+($L$12*(1+$C39)/(K$37-$C39))-WACC!$C$13+BS!$G$6)/IS!$G$42 -> 345.17681 | L39: =(NPV(L$37,$H$12,$I$12,$J$12,$K$12,$L$12)+($L$12*(1+$C39)/(L$37-$C39))-WACC!$C$13+BS!$G$6)/IS!$G$42 -> 340.00774
C40: =C41-0.05% -> 0.029 | D40: =(NPV(D$37,$H$12,$I$12,$J$12,$K$12,$L$12)+($L$12*(1+$C40)/(D$37-$C40))-WACC!$C$13+BS!$G$6)/IS!$G$42 -> 390.13873 | E40: =(NPV(E$37,$H$12,$I$12,$J$12,$K$12,$L$12)+($L$12*(1+$C40)/(E$37-$C40))-WACC!$C$13+BS!$G$6)/IS!$G$42 -> 383.44489 | F40: =(NPV(F$37,$H$12,$I$12,$J$12,$K$12,$L$12)+($L$12*(1+$C40)/(F$37-$C40))-WACC!$C$13+BS!$G$6)/IS!$G$42 -> 376.99109 | G40: =(NPV(G$37,$H$12,$I$12,$J$12,$K$12,$L$12)+($L$12*(1+$C40)/(G$37-$C40))-WACC!$C$13+BS!$G$6)/IS!$G$42 -> 370.7644 | H40: =(NPV(H$37,$H$12,$I$12,$J$12,$K$12,$L$12)+($L$12*(1+$C40)/(H$37-$C40))-WACC!$C$13+BS!$G$6)/IS!$G$42 -> 364.75284 | I40: =(NPV(I$37,$H$12,$I$12,$J$12,$K$12,$L$12)+($L$12*(1+$C40)/(I$37-$C40))-WACC!$C$13+BS!$G$6)/IS!$G$42 -> 358.94525 | J40: =(NPV(J$37,$H$12,$I$12,$J$12,$K$12,$L$12)+($L$12*(1+$C40)/(J$37-$C40))-WACC!$C$13+BS!$G$6)/IS!$G$42 -> 353.33122 | K40: =(NPV(K$37,$H$12,$I$12,$J$12,$K$12,$L$12)+($L$12*(1+$C40)/(K$37-$C40))-WACC!$C$13+BS!$G$6)/IS!$G$42 -> 347.90105 | L40: =(NPV(L$37,$H$12,$I$12,$J$12,$K$12,$L$12)+($L$12*(1+$C40)/(L$37-$C40))-WACC!$C$13+BS!$G$6)/IS!$G$42 -> 342.64568
C41: =C42-0.05% -> 0.0295 | D41: =(NPV(D$37,$H$12,$I$12,$J$12,$K$12,$L$12)+($L$12*(1+$C41)/(D$37-$C41))-WACC!$C$13+BS!$G$6)/IS!$G$42 -> 393.6756 | E41: =(NPV(E$37,$H$12,$I$12,$J$12,$K$12,$L$12)+($L$12*(1+$C41)/(E$37-$C41))-WACC!$C$13+BS!$G$6)/IS!$G$42 -> 386.8537 | F41: =(NPV(F$37,$H$12,$I$12,$J$12,$K$12,$L$12)+($L$12*(1+$C41)/(F$37-$C41))-WACC!$C$13+BS!$G$6)/IS!$G$42 -> 380.27877 | G41: =(NPV(G$37,$H$12,$I$12,$J$12,$K$12,$L$12)+($L$12*(1+$C41)/(G$37-$C41))-WACC!$C$13+BS!$G$6)/IS!$G$42 -> 373.93741 | H41: =(NPV(H$37,$H$12,$I$12,$J$12,$K$12,$L$12)+($L$12*(1+$C41)/(H$37-$C41))-WACC!$C$13+BS!$G$6)/IS!$G$42 -> 367.81717 | I41: =(NPV(I$37,$H$12,$I$12,$J$12,$K$12,$L$12)+($L$12*(1+$C41)/(I$37-$C41))-WACC!$C$13+BS!$G$6)/IS!$G$42 -> 361.90647 | J41: =(NPV(J$37,$H$12,$I$12,$J$12,$K$12,$L$12)+($L$12*(1+$C41)/(J$37-$C41))-WACC!$C$13+BS!$G$6)/IS!$G$42 -> 356.19455 | K41: =(NPV(K$37,$H$12,$I$12,$J$12,$K$12,$L$12)+($L$12*(1+$C41)/(K$37-$C41))-WACC!$C$13+BS!$G$6)/IS!$G$42 -> 350.67134 | L41: =(NPV(L$37,$H$12,$I$12,$J$12,$K$12,$L$12)+($L$12*(1+$C41)/(L$37-$C41))-WACC!$C$13+BS!$G$6)/IS!$G$42 -> 345.32747
C42: ='Inputs & Assumptions'!$D$7 -> 0.03 | D42: =(NPV(D$37,$H$12,$I$12,$J$12,$K$12,$L$12)+($L$12*(1+$C42)/(D$37-$C42))-WACC!$C$13+BS!$G$6)/IS!$G$42 -> 397.28094 | E42: =(NPV(E$37,$H$12,$I$12,$J$12,$K$12,$L$12)+($L$12*(1+$C42)/(E$37-$C42))-WACC!$C$13+BS!$G$6)/IS!$G$42 -> 390.32725 | F42: =(NPV(F$37,$H$12,$I$12,$J$12,$K$12,$L$12)+($L$12*(1+$C42)/(F$37-$C42))-WACC!$C$13+BS!$G$6)/IS!$G$42 -> 383.62773 | G42: =(NPV(G$37,$H$12,$I$12,$J$12,$K$12,$L$12)+($L$12*(1+$C42)/(G$37-$C42))-WACC!$C$13+BS!$G$6)/IS!$G$42 -> 377.16847 | H42: =(NPV(H$37,$H$12,$I$12,$J$12,$K$12,$L$12)+($L$12*(1+$C42)/(H$37-$C42))-WACC!$C$13+BS!$G$6)/IS!$G$42 -> 370.93655 | I42: =(NPV(I$37,$H$12,$I$12,$J$12,$K$12,$L$12)+($L$12*(1+$C42)/(I$37-$C42))-WACC!$C$13+BS!$G$6)/IS!$G$42 -> 364.91996 | J42: =(NPV(J$37,$H$12,$I$12,$J$12,$K$12,$L$12)+($L$12*(1+$C42)/(J$37-$C42))-WACC!$C$13+BS!$G$6)/IS!$G$42 -> 359.10753 | K42: =(NPV(K$37,$H$12,$I$12,$J$12,$K$12,$L$12)+($L$12*(1+$C42)/(K$37-$C42))-WACC!$C$13+BS!$G$6)/IS!$G$42 -> 353.48885 | L42: =(NPV(L$37,$H$12,$I$12,$J$12,$K$12,$L$12)+($L$12*(1+$C42)/(L$37-$C42))-WACC!$C$13+BS!$G$6)/IS!$G$42 -> 348.05421
C43: =C42+0.05% -> 0.0305 | D43: =(NPV(D$37,$H$12,$I$12,$J$12,$K$12,$L$12)+($L$12*(1+$C43)/(D$37-$C43))-WACC!$C$13+BS!$G$6)/IS!$G$42 -> 400.95675 | E43: =(NPV(E$37,$H$12,$I$12,$J$12,$K$12,$L$12)+($L$12*(1+$C43)/(E$37-$C43))-WACC!$C$13+BS!$G$6)/IS!$G$42 -> 393.86739 | F43: =(NPV(F$37,$H$12,$I$12,$J$12,$K$12,$L$12)+($L$12*(1+$C43)/(F$37-$C43))-WACC!$C$13+BS!$G$6)/IS!$G$42 -> 387.03969 | G43: =(NPV(G$37,$H$12,$I$12,$J$12,$K$12,$L$12)+($L$12*(1+$C43)/(G$37-$C43))-WACC!$C$13+BS!$G$6)/IS!$G$42 -> 380.4592 | H43: =(NPV(H$37,$H$12,$I$12,$J$12,$K$12,$L$12)+($L$12*(1+$C43)/(H$37-$C43))-WACC!$C$13+BS!$G$6)/IS!$G$42 -> 374.11249 | I43: =(NPV(I$37,$H$12,$I$12,$J$12,$K$12,$L$12)+($L$12*(1+$C43)/(I$37-$C43))-WACC!$C$13+BS!$G$6)/IS!$G$42 -> 367.98711 | J43: =(NPV(J$37,$H$12,$I$12,$J$12,$K$12,$L$12)+($L$12*(1+$C43)/(J$37-$C43))-WACC!$C$13+BS!$G$6)/IS!$G$42 -> 362.07148 | K43: =(NPV(K$37,$H$12,$I$12,$J$12,$K$12,$L$12)+($L$12*(1+$C43)/(K$37-$C43))-WACC!$C$13+BS!$G$6)/IS!$G$42 -> 356.35481 | L43: =(NPV(L$37,$H$12,$I$12,$J$12,$K$12,$L$12)+($L$12*(1+$C43)/(L$37-$C43))-WACC!$C$13+BS!$G$6)/IS!$G$42 -> 350.82704
C44: =C43+0.05% -> 0.031 | D44: =(NPV(D$37,$H$12,$I$12,$J$12,$K$12,$L$12)+($L$12*(1+$C44)/(D$37-$C44))-WACC!$C$13+BS!$G$6)/IS!$G$42 -> 404.70512 | E44: =(NPV(E$37,$H$12,$I$12,$J$12,$K$12,$L$12)+($L$12*(1+$C44)/(E$37-$C44))-WACC!$C$13+BS!$G$6)/IS!$G$42 -> 397.47606 | F44: =(NPV(F$37,$H$12,$I$12,$J$12,$K$12,$L$12)+($L$12*(1+$C44)/(F$37-$C44))-WACC!$C$13+BS!$G$6)/IS!$G$42 -> 390.51645 | G44: =(NPV(G$37,$H$12,$I$12,$J$12,$K$12,$L$12)+($L$12*(1+$C44)/(G$37-$C44))-WACC!$C$13+BS!$G$6)/IS!$G$42 -> 383.81125 | H44: =(NPV(H$37,$H$12,$I$12,$J$12,$K$12,$L$12)+($L$12*(1+$C44)/(H$37-$C44))-WACC!$C$13+BS!$G$6)/IS!$G$42 -> 377.34653 | I44: =(NPV(I$37,$H$12,$I$12,$J$12,$K$12,$L$12)+($L$12*(1+$C44)/(I$37-$C44))-WACC!$C$13+BS!$G$6)/IS!$G$42 -> 371.10937 | J44: =(NPV(J$37,$H$12,$I$12,$J$12,$K$12,$L$12)+($L$12*(1+$C44)/(J$37-$C44))-WACC!$C$13+BS!$G$6)/IS!$G$42 -> 365.08775 | K44: =(NPV(K$37,$H$12,$I$12,$J$12,$K$12,$L$12)+($L$12*(1+$C44)/(K$37-$C44))-WACC!$C$13+BS!$G$6)/IS!$G$42 -> 359.27048 | L44: =(NPV(L$37,$H$12,$I$12,$J$12,$K$12,$L$12)+($L$12*(1+$C44)/(L$37-$C44))-WACC!$C$13+BS!$G$6)/IS!$G$42 -> 353.64714
C45: =C44+0.05% -> 0.0315 | D45: =(NPV(D$37,$H$12,$I$12,$J$12,$K$12,$L$12)+($L$12*(1+$C45)/(D$37-$C45))-WACC!$C$13+BS!$G$6)/IS!$G$42 -> 408.52823 | E45: =(NPV(E$37,$H$12,$I$12,$J$12,$K$12,$L$12)+($L$12*(1+$C45)/(E$37-$C45))-WACC!$C$13+BS!$G$6)/IS!$G$42 -> 401.15527 | F45: =(NPV(F$37,$H$12,$I$12,$J$12,$K$12,$L$12)+($L$12*(1+$C45)/(F$37-$C45))-WACC!$C$13+BS!$G$6)/IS!$G$42 -> 394.05986 | G45: =(NPV(G$37,$H$12,$I$12,$J$12,$K$12,$L$12)+($L$12*(1+$C45)/(G$37-$C45))-WACC!$C$13+BS!$G$6)/IS!$G$42 -> 387.22636 | H45: =(NPV(H$37,$H$12,$I$12,$J$12,$K$12,$L$12)+($L$12*(1+$C45)/(H$37-$C45))-WACC!$C$13+BS!$G$6)/IS!$G$42 -> 380.64029 | I45: =(NPV(I$37,$H$12,$I$12,$J$12,$K$12,$L$12)+($L$12*(1+$C45)/(I$37-$C45))-WACC!$C$13+BS!$G$6)/IS!$G$42 -> 374.28824 | J45: =(NPV(J$37,$H$12,$I$12,$J$12,$K$12,$L$12)+($L$12*(1+$C45)/(J$37-$C45))-WACC!$C$13+BS!$G$6)/IS!$G$42 -> 368.15772 | K45: =(NPV(K$37,$H$12,$I$12,$J$12,$K$12,$L$12)+($L$12*(1+$C45)/(K$37-$C45))-WACC!$C$13+BS!$G$6)/IS!$G$42 -> 362.23715 | L45: =(NPV(L$37,$H$12,$I$12,$J$12,$K$12,$L$12)+($L$12*(1+$C45)/(L$37-$C45))-WACC!$C$13+BS!$G$6)/IS!$G$42 -> 356.51573
C46: =C45+0.05% -> 0.032 | D46: =(NPV(D$37,$H$12,$I$12,$J$12,$K$12,$L$12)+($L$12*(1+$C46)/(D$37-$C46))-WACC!$C$13+BS!$G$6)/IS!$G$42 -> 412.42832 | E46: =(NPV(E$37,$H$12,$I$12,$J$12,$K$12,$L$12)+($L$12*(1+$C46)/(E$37-$C46))-WACC!$C$13+BS!$G$6)/IS!$G$42 -> 404.90711 | F46: =(NPV(F$37,$H$12,$I$12,$J$12,$K$12,$L$12)+($L$12*(1+$C46)/(F$37-$C46))-WACC!$C$13+BS!$G$6)/IS!$G$42 -> 397.67186 | G46: =(NPV(G$37,$H$12,$I$12,$J$12,$K$12,$L$12)+($L$12*(1+$C46)/(G$37-$C46))-WACC!$C$13+BS!$G$6)/IS!$G$42 -> 390.70632 | H46: =(NPV(H$37,$H$12,$I$12,$J$12,$K$12,$L$12)+($L$12*(1+$C46)/(H$37-$C46))-WACC!$C$13+BS!$G$6)/IS!$G$42 -> 383.99543 | I46: =(NPV(I$37,$H$12,$I$12,$J$12,$K$12,$L$12)+($L$12*(1+$C46)/(I$37-$C46))-WACC!$C$13+BS!$G$6)/IS!$G$42 -> 377.52526 | J46: =(NPV(J$37,$H$12,$I$12,$J$12,$K$12,$L$12)+($L$12*(1+$C46)/(J$37-$C46))-WACC!$C$13+BS!$G$6)/IS!$G$42 -> 371.28285 | K46: =(NPV(K$37,$H$12,$I$12,$J$12,$K$12,$L$12)+($L$12*(1+$C46)/(K$37-$C46))-WACC!$C$13+BS!$G$6)/IS!$G$42 -> 365.25619 | L46: =(NPV(L$37,$H$12,$I$12,$J$12,$K$12,$L$12)+($L$12*(1+$C46)/(L$37-$C46))-WACC!$C$13+BS!$G$6)/IS!$G$42 -> 359.43408
B48: Target Return | C48: TGR/WACC | D48: =E48-0.001 -> 0.081658433 | E48: =F48-0.001 -> 0.082658433 | F48: =G48-0.001 -> 0.083658433 | G48: =_xlfn.XLOOKUP('Inputs & Assumptions'!$D$6,'Inputs & Assumptions'!$B$29:$B$32,'Inputs & Assumptions'!$C$29:$C$32,'Inputs & Assumptions'!$C$29) -> 0.084658433 | H48: =G48+0.001 -> 0.085658433 | I48: =H48+0.001 -> 0.086658433 | J48: =I48+0.001 -> 0.087658433 | K48: =J48+0.001 -> 0.088658433 | L48: =K48+0.001 -> 0.089658433
C49: =C50-0.05% -> 0.028 | D49: =((NPV(D$37,$H$12,$I$12,$J$12,$K$12,$L$12)+($L$12*(1+$C49)/(D$37-$C49))-WACC!$C$13+BS!$G$6)/IS!$G$42)/$C$24-1 -> 0.32971144 | E49: =((NPV(E$37,$H$12,$I$12,$J$12,$K$12,$L$12)+($L$12*(1+$C49)/(E$37-$C49))-WACC!$C$13+BS!$G$6)/IS!$G$42)/$C$24-1 -> 0.30733917 | F49: =((NPV(F$37,$H$12,$I$12,$J$12,$K$12,$L$12)+($L$12*(1+$C49)/(F$37-$C49))-WACC!$C$13+BS!$G$6)/IS!$G$42)/$C$24-1 -> 0.28575413 | G49: =((NPV(G$37,$H$12,$I$12,$J$12,$K$12,$L$12)+($L$12*(1+$C49)/(G$37-$C49))-WACC!$C$13+BS!$G$6)/IS!$G$42)/$C$24-1 -> 0.26491476 | H49: =((NPV(H$37,$H$12,$I$12,$J$12,$K$12,$L$12)+($L$12*(1+$C49)/(H$37-$C49))-WACC!$C$13+BS!$G$6)/IS!$G$42)/$C$24-1 -> 0.24478237 | I49: =((NPV(I$37,$H$12,$I$12,$J$12,$K$12,$L$12)+($L$12*(1+$C49)/(I$37-$C49))-WACC!$C$13+BS!$G$6)/IS!$G$42)/$C$24-1 -> 0.2253209 | J49: =((NPV(J$37,$H$12,$I$12,$J$12,$K$12,$L$12)+($L$12*(1+$C49)/(J$37-$C49))-WACC!$C$13+BS!$G$6)/IS!$G$42)/$C$24-1 -> 0.20649672 | K49: =((NPV(K$37,$H$12,$I$12,$J$12,$K$12,$L$12)+($L$12*(1+$C49)/(K$37-$C49))-WACC!$C$13+BS!$G$6)/IS!$G$42)/$C$24-1 -> 0.18827842 | L49: =((NPV(L$37,$H$12,$I$12,$J$12,$K$12,$L$12)+($L$12*(1+$C49)/(L$37-$C49))-WACC!$C$13+BS!$G$6)/IS!$G$42)/$C$24-1 -> 0.1706366
C50: =C51-0.05% -> 0.0285 | D50: =((NPV(D$37,$H$12,$I$12,$J$12,$K$12,$L$12)+($L$12*(1+$C50)/(D$37-$C50))-WACC!$C$13+BS!$G$6)/IS!$G$42)/$C$24-1 -> 0.34152722 | E50: =((NPV(E$37,$H$12,$I$12,$J$12,$K$12,$L$12)+($L$12*(1+$C50)/(E$37-$C50))-WACC!$C$13+BS!$G$6)/IS!$G$42)/$C$24-1 -> 0.31873512 | F50: =((NPV(F$37,$H$12,$I$12,$J$12,$K$12,$L$12)+($L$12*(1+$C50)/(F$37-$C50))-WACC!$C$13+BS!$G$6)/IS!$G$42)/$C$24-1 -> 0.2967526 | G50: =((NPV(G$37,$H$12,$I$12,$J$12,$K$12,$L$12)+($L$12*(1+$C50)/(G$37-$C50))-WACC!$C$13+BS!$G$6)/IS!$G$42)/$C$24-1 -> 0.27553651 | H50: =((NPV(H$37,$H$12,$I$12,$J$12,$K$12,$L$12)+($L$12*(1+$C50)/(H$37-$C50))-WACC!$C$13+BS!$G$6)/IS!$G$42)/$C$24-1 -> 0.25504674 | I50: =((NPV(I$37,$H$12,$I$12,$J$12,$K$12,$L$12)+($L$12*(1+$C50)/(I$37-$C50))-WACC!$C$13+BS!$G$6)/IS!$G$42)/$C$24-1 -> 0.23524594 | J50: =((NPV(J$37,$H$12,$I$12,$J$12,$K$12,$L$12)+($L$12*(1+$C50)/(J$37-$C50))-WACC!$C$13+BS!$G$6)/IS!$G$42)/$C$24-1 -> 0.21609927 | K50: =((NPV(K$37,$H$12,$I$12,$J$12,$K$12,$L$12)+($L$12*(1+$C50)/(K$37-$C50))-WACC!$C$13+BS!$G$6)/IS!$G$42)/$C$24-1 -> 0.19757421 | L50: =((NPV(L$37,$H$12,$I$12,$J$12,$K$12,$L$12)+($L$12*(1+$C50)/(L$37-$C50))-WACC!$C$13+BS!$G$6)/IS!$G$42)/$C$24-1 -> 0.17964036
C51: =C52-0.05% -> 0.029 | D51: =((NPV(D$37,$H$12,$I$12,$J$12,$K$12,$L$12)+($L$12*(1+$C51)/(D$37-$C51))-WACC!$C$13+BS!$G$6)/IS!$G$42)/$C$24-1 -> 0.35356739 | E51: =((NPV(E$37,$H$12,$I$12,$J$12,$K$12,$L$12)+($L$12*(1+$C51)/(E$37-$C51))-WACC!$C$13+BS!$G$6)/IS!$G$42)/$C$24-1 -> 0.33034345 | F51: =((NPV(F$37,$H$12,$I$12,$J$12,$K$12,$L$12)+($L$12*(1+$C51)/(F$37-$C51))-WACC!$C$13+BS!$G$6)/IS!$G$42)/$C$24-1 -> 0.30795228 | G51: =((NPV(G$37,$H$12,$I$12,$J$12,$K$12,$L$12)+($L$12*(1+$C51)/(G$37-$C51))-WACC!$C$13+BS!$G$6)/IS!$G$42)/$C$24-1 -> 0.28634909 | H51: =((NPV(H$37,$H$12,$I$12,$J$12,$K$12,$L$12)+($L$12*(1+$C51)/(H$37-$C51))-WACC!$C$13+BS!$G$6)/IS!$G$42)/$C$24-1 -> 0.26549228 | I51: =((NPV(I$37,$H$12,$I$12,$J$12,$K$12,$L$12)+($L$12*(1+$C51)/(I$37-$C51))-WACC!$C$13+BS!$G$6)/IS!$G$42)/$C$24-1 -> 0.24534312 | J51: =((NPV(J$37,$H$12,$I$12,$J$12,$K$12,$L$12)+($L$12*(1+$C51)/(J$37-$C51))-WACC!$C$13+BS!$G$6)/IS!$G$42)/$C$24-1 -> 0.22586552 | K51: =((NPV(K$37,$H$12,$I$12,$J$12,$K$12,$L$12)+($L$12*(1+$C51)/(K$37-$C51))-WACC!$C$13+BS!$G$6)/IS!$G$42)/$C$24-1 -> 0.20702582 | L51: =((NPV(L$37,$H$12,$I$12,$J$12,$K$12,$L$12)+($L$12*(1+$C51)/(L$37-$C51))-WACC!$C$13+BS!$G$6)/IS!$G$42)/$C$24-1 -> 0.18879256
C52: =C53-0.05% -> 0.0295 | D52: =((NPV(D$37,$H$12,$I$12,$J$12,$K$12,$L$12)+($L$12*(1+$C52)/(D$37-$C52))-WACC!$C$13+BS!$G$6)/IS!$G$42)/$C$24-1 -> 0.36583839 | E52: =((NPV(E$37,$H$12,$I$12,$J$12,$K$12,$L$12)+($L$12*(1+$C52)/(E$37-$C52))-WACC!$C$13+BS!$G$6)/IS!$G$42)/$C$24-1 -> 0.34217016 | F52: =((NPV(F$37,$H$12,$I$12,$J$12,$K$12,$L$12)+($L$12*(1+$C52)/(F$37-$C52))-WACC!$C$13+BS!$G$6)/IS!$G$42)/$C$24-1 -> 0.31935876 | G52: =((NPV(G$37,$H$12,$I$12,$J$12,$K$12,$L$12)+($L$12*(1+$C52)/(G$37-$C52))-WACC!$C$13+BS!$G$6)/IS!$G$42)/$C$24-1 -> 0.2973577 | H52: =((NPV(H$37,$H$12,$I$12,$J$12,$K$12,$L$12)+($L$12*(1+$C52)/(H$37-$C52))-WACC!$C$13+BS!$G$6)/IS!$G$42)/$C$24-1 -> 0.27612382 | I52: =((NPV(I$37,$H$12,$I$12,$J$12,$K$12,$L$12)+($L$12*(1+$C52)/(I$37-$C52))-WACC!$C$13+BS!$G$6)/IS!$G$42)/$C$24-1 -> 0.25561695 | J52: =((NPV(J$37,$H$12,$I$12,$J$12,$K$12,$L$12)+($L$12*(1+$C52)/(J$37-$C52))-WACC!$C$13+BS!$G$6)/IS!$G$42)/$C$24-1 -> 0.2357997 | K52: =((NPV(K$37,$H$12,$I$12,$J$12,$K$12,$L$12)+($L$12*(1+$C52)/(K$37-$C52))-WACC!$C$13+BS!$G$6)/IS!$G$42)/$C$24-1 -> 0.21663719 | L52: =((NPV(L$37,$H$12,$I$12,$J$12,$K$12,$L$12)+($L$12*(1+$C52)/(L$37-$C52))-WACC!$C$13+BS!$G$6)/IS!$G$42)/$C$24-1 -> 0.19809689
C53: ='Inputs & Assumptions'!$D$7 -> 0.03 | D53: =((NPV(D$37,$H$12,$I$12,$J$12,$K$12,$L$12)+($L$12*(1+$C53)/(D$37-$C53))-WACC!$C$13+BS!$G$6)/IS!$G$42)/$C$24-1 -> 0.37834694 | E53: =((NPV(E$37,$H$12,$I$12,$J$12,$K$12,$L$12)+($L$12*(1+$C53)/(E$37-$C53))-WACC!$C$13+BS!$G$6)/IS!$G$42)/$C$24-1 -> 0.35422146 | F53: =((NPV(F$37,$H$12,$I$12,$J$12,$K$12,$L$12)+($L$12*(1+$C53)/(F$37-$C53))-WACC!$C$13+BS!$G$6)/IS!$G$42)/$C$24-1 -> 0.33097781 | G53: =((NPV(G$37,$H$12,$I$12,$J$12,$K$12,$L$12)+($L$12*(1+$C53)/(G$37-$C53))-WACC!$C$13+BS!$G$6)/IS!$G$42)/$C$24-1 -> 0.30856772 | H53: =((NPV(H$37,$H$12,$I$12,$J$12,$K$12,$L$12)+($L$12*(1+$C53)/(H$37-$C53))-WACC!$C$13+BS!$G$6)/IS!$G$42)/$C$24-1 -> 0.28694637 | I53: =((NPV(I$37,$H$12,$I$12,$J$12,$K$12,$L$12)+($L$12*(1+$C53)/(I$37-$C53))-WACC!$C$13+BS!$G$6)/IS!$G$42)/$C$24-1 -> 0.26607211 | J53: =((NPV(J$37,$H$12,$I$12,$J$12,$K$12,$L$12)+($L$12*(1+$C53)/(J$37-$C53))-WACC!$C$13+BS!$G$6)/IS!$G$42)/$C$24-1 -> 0.24590617 | K53: =((NPV(K$37,$H$12,$I$12,$J$12,$K$12,$L$12)+($L$12*(1+$C53)/(K$37-$C53))-WACC!$C$13+BS!$G$6)/IS!$G$42)/$C$24-1 -> 0.22641242 | L53: =((NPV(L$37,$H$12,$I$12,$J$12,$K$12,$L$12)+($L$12*(1+$C53)/(L$37-$C53))-WACC!$C$13+BS!$G$6)/IS!$G$42)/$C$24-1 -> 0.20755718
...

Sheet WACC
B2: WACC | C2: =(C4*C8/SUM(C13,C10,C4))+(C10*C11/SUM(C13,C10,C4))+(C13*C15/SUM(C13,C10,C4)) -> 0.084658433
B4: Equity | C4: =BS!G42 -> 2311271
B5: Risk Free Rate | C5: ='Inputs & Assumptions'!$D$8 -> 0.0402
B6: Market Return | C6: -0.0091
B7: Beta | C7: 1.7
B8: Cost of equity | C8: =C5+C7*(C6+C5) -> 0.09307
B10: Preferred Equity | C10: 0
B11: Cost of preferred equity | C11: 0
B13: Total Debt | C13: =SUM(BS!G25:G26,BS!G30:G31) -> 335128
B14: Interest Expense | C14: =IS!G28 -> 8930
B15: Cost of debt | C15: =C14/C13 -> 0.026646535

Sheet Comparables
D2: Multiples | I2: Market Data (Oct 2025) | M2: Financial Data (YE 2024, $bn)
B3: Company | D3: EV/Sales | E3: EV/EBITDA | F3: P/E | G3: P/S | I3: Ticker | J3: Price | K3: Shares (m) | L3: Market Cap ($bn) | M3: EV ($bn) | N3: Sales | O3: EBITDA | P3: EBIT | Q3: Net Income
B4: Old Dominion Freight Line | D4: =M4/N4 -> 5.1118761 | E4: =M4/O4 -> 15.631579 | F4: =L4/Q4 -> 24.725882 | G4: =L4/N4 -> 5.0643373 | I4: ODFL | J4: 140 | K4: 210.17 | L4: =K4*J4/1000 -> 29.4238 | M4: 29.7 | N4: 5.81 | O4: 1.9 | P4: 1.56 | Q4: 1.19
